Workbook

Sheet DATA-OIL
A1: https://ec.europa.eu/eurostat/databrowser/view/NRG_CB_OIL__custom_11906154/default/table?lang=en
A2: Supply, transformation and consumption of oil and petroleum products
A5: Data extracted on 25/06/2025 13:27:20 from [ESTAT]
A6: Dataset: | B6: Supply, transformation and consumption of oil and petroleum products [nrg_cb_oil__custom_11906154]
A7: Last updated: | B7: 45833.458
A9: Time frequency | C9: Annual
A10: Unit of measure | C10: Thousand tonnes
A11: Geopolitical entity (reporting) | C11: European Union - 27 countries (from 2020)
A13: TIME | B13: TIME | C13: 1990 | D13: 1991 | E13: 1992 | F13: 1993 | G13: 1994 | H13: 1995 | I13: 1996 | J13: 1997 | K13: 1998 | L13: 1999 | M13: 2000 | N13: 2001 | O13: 2002 | P13: 2003 | Q13: 2004 | R13: 2005 | S13: 2006 | T13: 2007 | U13: 2008 | V13: 2009 | W13: 2010 | X13: 2011 | Y13: 2012 | Z13: 2013 | AA13: 2014 | AB13: 2015 | AC13: 2016 | AD13: 2017 | AE13: 2018 | AF13: 2019 | AG13: 2020 | AH13: 2021 | AI13: 2022 | AJ13: 2023 | AK13: 2024
A14: SIEC (Labels) | B14: NRG_BAL (Labels)
A15: Oil and petroleum products | B15: Indigenous production | C15: 40179 | D15: 38934.9 | E15: 38690.6 | F15: 38565.6 | G15: 40102.7 | H15: 39315.9 | I15: 38995.8 | J15: 39962.2 | K15: 39298.9 | L15: 40561.3 | M15: 43871 | N15: 41905 | O15: 46800 | P15: 46864 | Q15: 46345 | R15: 45545.786 | S15: 42693.14 | T15: 40614.23 | U15: 38034.386 | V15: 34703.223 | W15: 33185.002 | X15: 31460.979 | Y15: 30224.903 | Z15: 29391.375 | AA15: 29006.891 | AB15: 28201.078 | AC15: 25211.285 | AD15: 25073.924 | AE15: 24573.253 | AF15: 22755.252 | AG15: 21445.329 | AH15: 20209.433 | AI15: 18838.68 | AJ15: 19057.031 | AK15: 17981.282
A16: Oil and petroleum products | B16: Imports | C16: 734076.41 | D16: 717812.22 | E16: 724229.21 | F16: 728577.44 | G16: 736509.9 | H16: 735994.9 | I16: 761875.66 | J16: 773656 | K16: 801986.05 | L16: 770601.81 | M16: 792731.36 | N16: 802352.24 | O16: 796912.35 | P16: 816005.22 | Q16: 843240.47 | R16: 867331.09 | S16: 874177.47 | T16: 852561.91 | U16: 866729.13 | V16: 822409.12 | W16: 830457.06 | X16: 810816.43 | Y16: 811036.17 | Z16: 801133.19 | AA16: 796775.4 | AB16: 848637.19 | AC16: 853437.69 | AD16: 868407 | AE16: 856723.99 | AF16: 846962.23 | AG16: 745108.41 | AH16: 770747.6 | AI16: 808887.1 | AJ16: 785477.61 | AK16: 790837.42
A17: Oil and petroleum products | B17: Exports | C17: 189919.42 | D17: 172739.9 | E17: 175971.27 | F17: 186644.8 | G17: 189489.06 | H17: 178508.45 | I17: 186748 | J17: 194195.46 | K17: 198974.4 | L17: 197937.7 | M17: 216892.99 | N17: 212488.51 | O17: 214965.35 | P17: 223444.29 | Q17: 249698.69 | R17: 267681.3 | S17: 273457.56 | T17: 269289.99 | U17: 277622.99 | V17: 273077.99 | W17: 285079.64 | X17: 283128.35 | Y17: 304709.16 | Z17: 307444.9 | AA17: 308984.89 | AB17: 341539.2 | AC17: 350855.83 | AD17: 357793.44 | AE17: 346301.94 | AF17: 326132.83 | AG17: 291668.03 | AH17: 318470.34 | AI17: 313723.94 | AJ17: 314402.25 | AK17: 314630.27
A18: Oil and petroleum products | B18: Gross inland deliveries | C18: 529267.33 | D18: 536663.98 | E18: 537195.66 | F18: 530270.04 | G18: 536855.19 | H18: 545861.74 | I18: 557638.83 | J18: 562615.12 | K18: 574527.21 | L18: 566911.05 | M18: 559736.19 | N18: 569350.16 | O18: 565253.24 | P18: 569459.28 | Q18: 571454.98 | R18: 570756.7 | S18: 570661.84 | T18: 556466.45 | U18: 553267.84 | V18: 524432.26 | W18: 525091.39 | X18: 511841.17 | Y18: 494744.67 | Z18: 480987.86 | AA18: 478063.41 | AB18: 485001.4 | AC18: 488718.13 | AD18: 501026.03 | AE18: 496825.58 | AF18: 498114.35 | AG18: 438350.25 | AH18: 461104.45 | AI18: 473022.18 | AJ18: 463027.87 | AK18: :
A19: Oil and petroleum products | B19: Gross inland deliveries - calculated | C19: 529837.7 | D19: 534957.29 | E19: 530830.49 | F19: 529688.87 | G19: 530928.96 | H19: 541363.44 | I19: 554488.46 | J19: 559088.04 | K19: 572838.05 | L19: 563406.63 | M19: 552553.72 | N19: 569386.62 | O19: 565183.14 | P19: 568523.66 | Q19: 569602.61 | R19: 565761.7 | S19: 566898.09 | T19: 551361.31 | U19: 554235.6 | V19: 527057.46 | W19: 526678.39 | X19: 513824.13 | Y19: 494098.24 | Z19: 478723.11 | AA19: 477887.5 | AB19: 485043.71 | AC19: 488400.77 | AD19: 503819.47 | AE19: 499898.22 | AF19: 499840.2 | AG19: 438262.11 | AH19: 457929.15 | AI19: 468005.63 | AJ19: 463366.46 | AK19: 456583.88
A20: Oil and petroleum products | B20: Gross inland deliveries - observed | C20: 529267.33 | D20: 536663.98 | E20: 537195.66 | F20: 530270.04 | G20: 536855.19 | H20: 545861.74 | I20: 557638.83 | J20: 562615.12 | K20: 574527.21 | L20: 566911.05 | M20: 559736.19 | N20: 569350.16 | O20: 565253.24 | P20: 569459.28 | Q20: 571454.98 | R20: 570756.7 | S20: 570661.84 | T20: 556466.45 | U20: 553267.84 | V20: 524432.26 | W20: 525091.39 | X20: 511841.17 | Y20: 494744.67 | Z20: 480987.86 | AA20: 478063.41 | AB20: 485001.4 | AC20: 488718.13 | AD20: 501026.03 | AE20: 496825.58 | AF20: 498114.35 | AG20: 438261.59 | AH20: 461104.45 | AI20: 473022.18 | AJ20: 463027.87 | AK20: :
A21: Oil and petroleum products (excluding biofuel portion) | B21: Indigenous production | C21: 40179 | D21: 38934.9 | E21: 38690.6 | F21: 38565.6 | G21: 40102.7 | H21: 39315.9 | I21: 38995.8 | J21: 39962.2 | K21: 39298.9 | L21: 40561.3 | M21: 43871 | N21: 41905 | O21: 46800 | P21: 46864 | Q21: 46345 | R21: 45545.786 | S21: 42693.14 | T21: 40614.23 | U21: 38034.386 | V21: 34703.223 | W21: 33185.002 | X21: 31460.979 | Y21: 30224.903 | Z21: 29391.375 | AA21: 29006.891 | AB21: 28201.078 | AC21: 25211.285 | AD21: 25073.924 | AE21: 24573.253 | AF21: 22755.252 | AG21: 21445.329 | AH21: 20209.433 | AI21: 18838.68 | AJ21: 19057.031 | AK21: 17981.282
A22: Oil and petroleum products (excluding biofuel portion) | B22: Imports | C22: 734076.41 | D22: 717812.22 | E22: 724229.21 | F22: 728577.44 | G22: 736509.9 | H22: 735994.9 | I22: 761875.66 | J22: 773656 | K22: 801986.05 | L22: 770601.81 | M22: 792731.36 | N22: 802352.24 | O22: 796912.35 | P22: 816005.22 | Q22: 843240.47 | R22: 867306.65 | S22: 873969.36 | T22: 852291.33 | U22: 866360.98 | V22: 821819.22 | W22: 829794.04 | X22: 809942.35 | Y22: 810311.62 | Z22: 800522.54 | AA22: 796084.97 | AB22: 847870.97 | AC22: 852645.13 | AD22: 867454.61 | AE22: 855690.51 | AF22: 845785.12 | AG22: 743881.25 | AH22: 769496.41 | AI22: 807653.69 | AJ22: 784227.26 | AK22: 789495.98
A23: Oil and petroleum products (excluding biofuel portion) | B23: Exports | C23: 189919.42 | D23: 172739.9 | E23: 175971.27 | F23: 186644.8 | G23: 189489.06 | H23: 178508.45 | I23: 186748 | J23: 194195.46 | K23: 198974.4 | L23: 197937.7 | M23: 216892.99 | N23: 212488.51 | O23: 214965.35 | P23: 223444.29 | Q23: 249698.69 | R23: 267681.19 | S23: 273380.27 | T23: 269217.29 | U23: 277238.05 | V23: 272646 | W23: 284677.95 | X23: 282673.4 | Y23: 304183.08 | Z23: 306942.12 | AA23: 308527.67 | AB23: 341038.96 | AC23: 350295.54 | AD23: 357189.27 | AE23: 345550.61 | AF23: 325266.37 | AG23: 290734.35 | AH23: 317638.55 | AI23: 312869.06 | AJ23: 313638.29 | AK23: 313755.46
A24: Oil and petroleum products (excluding biofuel portion) | B24: Gross inland deliveries | C24: 529267.33 | D24: 536663.98 | E24: 537183.66 | F24: 530218.04 | G24: 536724.19 | H24: 545657.74 | I24: 557334.83 | J24: 562215.12 | K24: 574163.21 | L24: 566530.05 | M24: 559192.19 | N24: 568770.16 | O24: 564529.24 | P24: 568600.28 | Q24: 569938.98 | R24: 568189.32 | S24: 566886.08 | T24: 550303.55 | U24: 543846.11 | V24: 512137.2 | W24: 511092.83 | X24: 496900.51 | Y24: 478754.32 | Z24: 466632.89 | AA24: 462779.96 | AB24: 469719.21 | AC24: 473550.24 | AD24: 484764.35 | AE24: 478735.83 | AF24: 479302.54 | AG24: 419364.1 | AH24: 441179.65 | AI24: 452948.45 | AJ24: 442044.14 | AK24: :
A25: Oil and petroleum products (excluding biofuel portion) | B25: Gross inland deliveries - calculated | C25: 529837.7 | D25: 534957.29 | E25: 530818.49 | F25: 529636.87 | G25: 530797.96 | H25: 541159.44 | I25: 554184.46 | J25: 558688.04 | K25: 572474.05 | L25: 563025.63 | M25: 552009.72 | N25: 568806.62 | O25: 564459.14 | P25: 567664.66 | Q25: 568086.61 | R25: 563178.41 | S25: 563118.98 | T25: 545328.67 | U25: 544846.2 | V25: 514731.17 | W25: 512663.72 | X25: 498838.31 | Y25: 478083.41 | Z25: 464440.17 | AA25: 462786.04 | AB25: 469828.78 | AC25: 473400.81 | AD25: 487254.42 | AE25: 482026.69 | AF25: 480996.76 | AG25: 419594.58 | AH25: 438044.41 | AI25: 448540.96 | AJ25: 442305.38 | AK25: 437373.42
A26: Oil and petroleum products (excluding biofuel portion) | B26: Gross inland deliveries - observed | C26: 529267.33 | D26: 536663.98 | E26: 537183.66 | F26: 530218.04 | G26: 536724.19 | H26: 545657.74 | I26: 557334.83 | J26: 562215.12 | K26: 574163.21 | L26: 566530.05 | M26: 559192.19 | N26: 568770.16 | O26: 564529.24 | P26: 568600.28 | Q26: 569938.98 | R26: 568189.32 | S26: 566886.08 | T26: 550303.55 | U26: 543846.11 | V26: 512137.2 | W26: 511092.83 | X26: 496900.51 | Y26: 478754.32 | Z26: 466632.89 | AA26: 462779.96 | AB26: 469719.21 | AC26: 473550.24 | AD26: 484764.35 | AE26: 478735.83 | AF26: 479302.54 | AG26: 419275.45 | AH26: 441179.65 | AI26: 452948.45 | AJ26: 442044.14 | AK26: :
A27: Oil products | B27: Indigenous production | C27: : | D27: : | E27: : | F27: : | G27: : | H27: : | I27: : | J27: : | K27: : | L27: : | M27: : | N27: : | O27: : | P27: : | Q27: : | R27: : | S27: : | T27: : | U27: : | V27: : | W27: : | X27: : | Y27: : | Z27: : | AA27: : | AB27: : | AC27: : | AD27: : | AE27: : | AF27: : | AG27: : | AH27: : | AI27: : | AJ27: : | AK27: :
A28: Oil products | B28: Imports | C28: 205762.78 | D28: 204465.1 | E28: 198926.1 | F28: 201745.59 | G28: 195193.61 | H28: 196093.44 | I28: 206548.27 | J28: 206672.07 | K28: 209434.08 | L28: 209376.38 | M28: 219735.18 | N28: 226906.7 | O28: 235167.26 | P28: 237100.31 | Q28: 250959.02 | R28: 272267.26 | S28: 279379.67 | T28: 265494.51 | U28: 278644.08 | V28: 279399.3 | W28: 290841.97 | X28: 289276.77 | Y28: 281785.03 | Z28: 289994.13 | AA28: 287816.44 | AB28: 306129.29 | AC28: 317325.64 | AD28: 318602.55 | AE28: 317536.71 | AF28: 316619.59 | AG28: 280797.21 | AH28: 297062.89 | AI28: 301680.68 | AJ28: 288398.08 | AK28: 293457.53
A29: Oil products | B29: Exports | C29: 172029.24 | D29: 161910.3 | E29: 162558.97 | F29: 172777.2 | G29: 173963.66 | H29: 165552.15 | I29: 172571 | J29: 176748.26 | K29: 183296.5 | L29: 178588.5 | M29: 192468.99 | N29: 194212.51 | O29: 193806.35 | P29: 201273.29 | Q29: 225604.69 | R29: 244421.46 | S29: 252494.35 | T29: 248766.93 | U29: 258741.43 | V29: 254742.1 | W29: 266747.07 | X29: 266963.84 | Y29: 286903 | Z29: 289812.65 | AA29: 291757.89 | AB29: 325324.77 | AC29: 335013.65 | AD29: 341222.55 | AE29: 331498.87 | AF29: 312671.71 | AG29: 278469.99 | AH29: 304474.01 | AI29: 301431.63 | AJ29: 299995.87 | AK29: 303354.82
A30: Oil products | B30: Gross inland deliveries | C30: 525765.87 | D30: 533376.89 | E30: 533891.84 | F30: 526051.58 | G30: 532563.1 | H30: 542148.28 | I30: 554195.74 | J30: 558666.4 | K30: 570474.85 | L30: 562708.6 | M30: 555149 | N30: 564849.61 | O30: 559823.87 | P30: 564642.1 | Q30: 566656.25 | R30: 565772.43 | S30: 565398.84 | T30: 552075.82 | U30: 549052.12 | V30: 520376.08 | W30: 521137.48 | X30: 507920.99 | Y30: 491162.21 | Z30: 477292.31 | AA30: 474475.5 | AB30: 481723.42 | AC30: 485267.17 | AD30: 497991.22 | AE30: 494240.45 | AF30: 495946.48 | AG30: 435991.29 | AH30: 458871.67 | AI30: 470562.5 | AJ30: 459309.59 | AK30: :
A31: Oil products | B31: Gross inland deliveries - calculated | C31: 526336.24 | D31: 531670.2 | E31: 527526.67 | F31: 525470.41 | G31: 526636.87 | H31: 537649.99 | I31: 551044.37 | J31: 555138.31 | K31: 568786.68 | L31: 559204.18 | M31: 547966.54 | N31: 564886.08 | O31: 559752.78 | P31: 563707.48 | Q31: 564803.88 | R31: 560777.43 | S31: 561635.09 | T31: 546970.67 | U31: 550018.88 | V31: 523001.28 | W31: 522724.48 | X31: 509901.95 | Y31: 490514.78 | Z31: 475028.57 | AA31: 474299.59 | AB31: 481765.73 | AC31: 484949.8 | AD31: 500784.66 | AE31: 497313.09 | AF31: 497672.32 | AG31: 435903.16 | AH31: 455696.37 | AI31: 465545.96 | AJ31: 459648.19 | AK31: 454038.37
A32: Oil products | B32: Gross inland deliveries - observed | C32: 525765.87 | D32: 533376.89 | E32: 533891.84 | F32: 526051.58 | G32: 532563.1 | H32: 542148.28 | I32: 554195.74 | J32: 558666.4 | K32: 570474.85 | L32: 562708.6 | M32: 555149 | N32: 564849.61 | O32: 559823.87 | P32: 564642.1 | Q32: 566656.25 | R32: 565772.43 | S32: 565398.84 | T32: 552075.82 | U32: 549052.12 | V32: 520376.08 | W32: 521137.48 | X32: 507920.99 | Y32: 491162.21 | Z32: 477292.31 | AA32: 474475.5 | AB32: 481723.42 | AC32: 485267.17 | AD32: 497991.22 | AE32: 494240.45 | AF32: 495946.48 | AG32: 435902.64 | AH32: 458871.67 | AI32: 470562.5 | AJ32: 459309.59 | AK32: :
A33: Oil products (excluding biofuel portion) | B33: Indigenous production | C33: : | D33: : | E33: : | F33: : | G33: : | H33: : | I33: : | J33: : | K33: : | L33: : | M33: : | N33: : | O33: : | P33: : | Q33: : | R33: : | S33: : | T33: : | U33: : | V33: : | W33: : | X33: : | Y33: : | Z33: : | AA33: : | AB33: : | AC33: : | AD33: : | AE33: : | AF33: : | AG33: : | AH33: : | AI33: : | AJ33: : | AK33: :
A34: Oil products (excluding biofuel portion) | B34: Imports | C34: 205762.78 | D34: 204465.1 | E34: 198926.1 | F34: 201745.59 | G34: 195193.61 | H34: 196093.44 | I34: 206548.27 | J34: 206672.07 | K34: 209434.08 | L34: 209376.38 | M34: 219735.18 | N34: 226906.7 | O34: 235167.26 | P34: 237100.31 | Q34: 250959.02 | R34: 272242.82 | S34: 279171.56 | T34: 265223.93 | U34: 278275.93 | V34: 278809.41 | W34: 290178.95 | X34: 288402.69 | Y34: 281060.48 | Z34: 289383.48 | AA34: 287126.01 | AB34: 305363.07 | AC34: 316533.08 | AD34: 317650.17 | AE34: 316503.23 | AF34: 315442.48 | AG34: 279570.05 | AH34: 295811.71 | AI34: 300447.27 | AJ34: 287147.72 | AK34: 292116.1
A35: Oil products (excluding biofuel portion) | B35: Exports | C35: 172029.24 | D35: 161910.3 | E35: 162558.97 | F35: 172777.2 | G35: 173963.66 | H35: 165552.15 | I35: 172571 | J35: 176748.26 | K35: 183296.5 | L35: 178588.5 | M35: 192468.99 | N35: 194212.51 | O35: 193806.35 | P35: 201273.29 | Q35: 225604.69 | R35: 244421.35 | S35: 252417.05 | T35: 248694.23 | U35: 258356.5 | V35: 254310.11 | W35: 266345.38 | X35: 266508.89 | Y35: 286376.92 | Z35: 289309.88 | AA35: 291300.67 | AB35: 324824.53 | AC35: 334453.36 | AD35: 340618.38 | AE35: 330747.54 | AF35: 311805.25 | AG35: 277536.3 | AH35: 303642.23 | AI35: 300576.75 | AJ35: 299231.91 | AK35: 302480.01
A36: Oil products (excluding biofuel portion) | B36: Gross inland deliveries | C36: 525765.87 | D36: 533376.89 | E36: 533879.84 | F36: 525999.58 | G36: 532432.1 | H36: 541944.28 | I36: 553891.74 | J36: 558266.4 | K36: 570110.85 | L36: 562327.6 | M36: 554605 | N36: 564269.61 | O36: 559099.87 | P36: 563783.1 | Q36: 565140.25 | R36: 563205.05 | S36: 561623.08 | T36: 545912.91 | U36: 539630.38 | V36: 508081.02 | W36: 507138.92 | X36: 492980.33 | Y36: 475171.86 | Z36: 462937.35 | AA36: 459192.05 | AB36: 466441.23 | AC36: 470099.28 | AD36: 481729.54 | AE36: 476150.7 | AF36: 477134.67 | AG36: 417005.15 | AH36: 438946.86 | AI36: 450488.78 | AJ36: 438325.86 | AK36: :
A37: Oil products (excluding biofuel portion) | B37: Gross inland deliveries - calculated | C37: 526336.24 | D37: 531670.2 | E37: 527514.67 | F37: 525418.41 | G37: 526505.87 | H37: 537445.99 | I37: 550740.37 | J37: 554738.31 | K37: 568422.68 | L37: 558823.18 | M37: 547422.54 | N37: 564306.08 | O37: 559028.78 | P37: 562848.48 | Q37: 563287.88 | R37: 558194.13 | S37: 557855.98 | T37: 540938.03 | U37: 540629.47 | V37: 510674.99 | W37: 508709.81 | X37: 494916.13 | Y37: 474499.96 | Z37: 460745.62 | AA37: 459198.13 | AB37: 466550.79 | AC37: 469949.85 | AD37: 484219.61 | AE37: 479441.55 | AF37: 478828.88 | AG37: 417235.62 | AH37: 435811.62 | AI37: 446081.28 | AJ37: 438587.1 | AK37: 434827.9
A38: Oil products (excluding biofuel portion) | B38: Gross inland deliveries - observed | C38: 525765.87 | D38: 533376.89 | E38: 533879.84 | F38: 525999.58 | G38: 532432.1 | H38: 541944.28 | I38: 553891.74 | J38: 558266.4 | K38: 570110.85 | L38: 562327.6 | M38: 554605 | N38: 564269.61 | O38: 559099.87 | P38: 563783.1 | Q38: 565140.25 | R38: 563205.05 | S38: 561623.08 | T38: 545912.91 | U38: 539630.38 | V38: 508081.02 | W38: 507138.92 | X38: 492980.33 | Y38: 475171.86 | Z38: 462937.35 | AA38: 459192.05 | AB38: 466441.23 | AC38: 470099.28 | AD38: 481729.54 | AE38: 476150.7 | AF38: 477134.67 | AG38: 416916.49 | AH38: 438946.86 | AI38: 450488.78 | AJ38: 438325.86 | AK38: :
A40: Special value
A41: : | B41: not available
A43: https://ec.europa.eu/eurostat/databrowser/view/NRG_CB_OIL__custom_11906162/default/table?lang=en
A44: Supply, transformation and consumption of oil and petroleum products
A47: Data extracted on 25/06/2025 13:31:16 from [ESTAT]
A48: Dataset: | B48: Supply, transformation and consumption of oil and petroleum products [nrg_cb_oil__custom_11906162]
...

Sheet DATA-COAL
A1: https://ec.europa.eu/eurostat/databrowser/bookmark/da69b178-3a1a-446b-a755-dee1c50c7a86?lang=en
A2: Supply, transformation and consumption of solid fossil fuels
A5: Data extracted on 25/06/2025 18:30:14 from [ESTAT]
A6: Dataset: | B6: Supply, transformation and consumption of solid fossil fuels [nrg_cb_sff__custom_17247811]
A7: Last updated: | B7: 24/06/2025 23:00
A9: Time frequency | C9: Annual
A10: Unit of measure | C10: Thousand tonnes
A11: Geopolitical entity (reporting) | C11: European Union - 27 countries (from 2020)
A13: TIME | B13: TIME | C13: 1990 | D13: 1991 | E13: 1992 | F13: 1993 | G13: 1994 | H13: 1995 | I13: 1996 | J13: 1997 | K13: 1998 | L13: 1999 | M13: 2000 | N13: 2001 | O13: 2002 | P13: 2003 | Q13: 2004 | R13: 2005 | S13: 2006 | T13: 2007 | U13: 2008 | V13: 2009 | W13: 2010 | X13: 2011 | Y13: 2012 | Z13: 2013 | AA13: 2014 | AB13: 2015 | AC13: 2016 | AD13: 2017 | AE13: 2018 | AF13: 2019 | AG13: 2020 | AH13: 2021 | AI13: 2022 | AJ13: 2023 | AK13: 2024
A14: SIEC (Labels) | B14: NRG_BAL (Labels)
A15: Solid fossil fuels | B15: Indigenous production | C15: 1085598.8 | D15: 948694.8 | E15: 881459.27 | F15: 838395.1 | G15: 804856.2 | H15: 787925.2 | I15: 778877.3 | J15: 750023.5 | K15: 692582.8 | L15: 653434.3 | M15: 657422 | N15: 662247 | O15: 660241 | P15: 661498 | Q15: 658637 | R15: 642471.76 | S15: 635668.85 | T15: 632802.02 | U15: 609689.55 | V15: 568893.88 | W15: 561815.15 | X15: 589071.75 | Y15: 595147.06 | Z15: 556642.38 | AA15: 540481.63 | AB15: 536898.19 | AC15: 500447.18 | AD15: 506299.65 | AE15: 485680.52 | AF15: 415081.12 | AG15: 338148.63 | AH15: 370813.27 | AI15: 386537.89 | AJ15: 308313.1 | AK15: 274881.65
A16: Solid fossil fuels | B16: Transfer from other sources | C16: 2459 | D16: 3401 | E16: 2285 | F16: 1954 | G16: 2209 | H16: 3725 | I16: 2808 | J16: 2111 | K16: 1419 | L16: 1880 | M16: 2125 | N16: 1305 | O16: 1592 | P16: 1848 | Q16: 3882 | R16: 1520 | S16: 1297 | T16: 1520 | U16: 1222 | V16: 826 | W16: 1024 | X16: 1125 | Y16: 1108 | Z16: 1125.5 | AA16: 1382.7 | AB16: 833 | AC16: 806.5 | AD16: 843.379 | AE16: 1143.908 | AF16: 1032.996 | AG16: 781.434 | AH16: 563.449 | AI16: 502.711 | AJ16: 567.7 | AK16: 553.172
A17: Solid fossil fuels | B17: Imports | C17: 177541.02 | D17: 177565.39 | E17: 170209.82 | F17: 147643.5 | G17: 153617.88 | H17: 162901.77 | I17: 162920.43 | J17: 163451.3 | K17: 163946.67 | L17: 157320.29 | M17: 173617.32 | N17: 179571.75 | O17: 181450.26 | P17: 188060.12 | Q17: 200350.94 | R17: 190516.96 | S17: 204886.73 | T17: 208858.54 | U17: 205918.88 | V17: 165792.51 | W17: 180278.08 | X17: 189414.89 | Y17: 188103.46 | Z17: 182464.22 | AA17: 184102.92 | AB17: 180133.48 | AC17: 172013.22 | AD17: 174992.33 | AE17: 166209.65 | AF17: 137029.83 | AG17: 96939.74 | AH17: 115510.43 | AI17: 138147.99 | AJ17: 101930.76 | AK17: 76072.703
A18: Solid fossil fuels | B18: Exports | C18: 65467.971 | D18: 55598 | E18: 50100 | F18: 48868 | G18: 54496 | H18: 58364.5 | I18: 51976.468 | J18: 51665.934 | K18: 48600 | L18: 42492 | M18: 42408 | N18: 42539 | O18: 41472 | P18: 38008 | Q18: 38868 | R18: 37402.5 | S18: 39139.098 | T18: 35627.435 | U18: 31822.352 | V18: 28486.59 | W18: 31685.012 | X18: 27326.447 | Y18: 28288.73 | Z18: 30326.266 | AA18: 30109.902 | AB18: 27620.079 | AC18: 26206.117 | AD18: 22493.592 | AE18: 19868.05 | AF18: 19471.652 | AG18: 19351.749 | AH18: 21994.799 | AI18: 21294.168 | AJ18: 23717.567 | AK18: 18857.699
A19: Solid fossil fuels | B19: Change in stock | C19: 13161.482 | D19: 4984.035 | E19: -10278.999 | F19: 10899.82 | G19: 13600.656 | H19: 4780.928 | I19: 3560.859 | J19: -3764.883 | K19: 9192.544 | L19: 5780.302 | M19: 9668.243 | N19: 5623.89 | O19: 1691.211 | P19: 9530.411 | Q19: -1073.069 | R19: 606.112 | S19: 5047.027 | T19: 6437.505 | U19: -16115.625 | V19: -6774.628 | W19: 7264.157 | X19: 295.154 | Y19: -4371.149 | Z19: 13232.289 | AA19: 2448.984 | AB19: 5217.949 | AC19: 12984.969 | AD19: 1393.28 | AE19: 3173.934 | AF19: -6266.019 | AG19: 10757.969 | AH19: 19887.819 | AI19: -8837.372 | AJ19: -3754.009 | AK19: 10729.358
A20: Solid fossil fuels | B20: International maritime bunkers | C20: 0 | D20: 0 | E20: 0 | F20: 0 | G20: 0 | H20: 0 | I20: 0 | J20: 0 | K20: 0 | L20: 0 | M20: 0 | N20: 0 | O20: 0 | P20: 0 | Q20: 0 | R20: 0 | S20: 0 | T20: 0 | U20: 0 | V20: 0 | W20: 0 | X20: 0 | Y20: 0 | Z20: 0 | AA20: 0 | AB20: 0 | AC20: 0 | AD20: 0 | AE20: 0 | AF20: 0 | AG20: 0 | AH20: 0 | AI20: 0 | AJ20: 0 | AK20: :
A21: Solid fossil fuels | B21: Inland consumption - calculated | C21: 1213292.3 | D21: 1079047.2 | E21: 993575.09 | F21: 950024.42 | G21: 919787.74 | H21: 900968.4 | I21: 896190.12 | J21: 860154.98 | K21: 818541.02 | L21: 775922.89 | M21: 800424.56 | N21: 806208.64 | O21: 803502.47 | P21: 822928.53 | Q21: 822928.87 | R21: 797712.33 | S21: 807760.52 | T21: 813990.63 | U21: 768892.45 | V21: 700251.17 | W21: 718696.37 | X21: 752580.34 | Y21: 751698.63 | Z21: 723138.12 | AA21: 698306.33 | AB21: 695462.54 | AC21: 660045.76 | AD21: 661035.05 | AE21: 636339.97 | AF21: 527406.28 | AG21: 427276.03 | AH21: 484780.17 | AI21: 495057.05 | AJ21: 383339.98 | AK21: 343379.19
A22: Hard coal | B22: Indigenous production | C22: 277420.51 | D22: 261037 | E22: 251049.27 | F22: 236744.6 | G22: 231356.2 | H22: 233296.2 | I22: 227824.4 | J22: 224534.5 | K22: 194246.8 | L22: 184048.3 | M22: 169332 | N22: 161885 | O22: 157904 | P22: 155503 | Q22: 152173 | R22: 147034 | S22: 139955 | T22: 132551 | U22: 122939 | V22: 110512 | W22: 107816 | X22: 104259 | Y22: 106230 | Z22: 95941 | AA22: 92315 | AB22: 88889 | AC22: 82318 | AD22: 75892.292 | AE22: 71297.093 | AF22: 65055.503 | AG22: 56531.347 | AH22: 57185.259 | AI22: 54512.515 | AJ22: 49721.789 | AK22: 45295.836
A23: Hard coal | B23: Transfer from other sources | C23: 1138 | D23: 1928 | E23: 1306 | F23: 983 | G23: 1456 | H23: 3088 | I23: 2248 | J23: 1684 | K23: 1107 | L23: 1516 | M23: 1750 | N23: 1087 | O23: 1419 | P23: 1719 | Q23: 3701 | R23: 1411 | S23: 1268 | T23: 1508 | U23: 961 | V23: 826 | W23: 1022 | X23: 1125 | Y23: 1108 | Z23: 1048 | AA23: 1302 | AB23: 766 | AC23: 694 | AD23: 738.379 | AE23: 669.278 | AF23: 578.128 | AG23: 393.112 | AH23: 370.644 | AI23: 378.529 | AJ23: 380.392 | AK23: 408.213
A24: Hard coal | B24: Imports | C24: 148225.75 | D24: 150987.39 | E24: 148870.66 | F24: 127556.2 | G24: 134684.71 | H24: 143793.97 | I24: 145074.99 | J24: 147055.56 | K24: 147886.52 | L24: 142442.13 | M24: 155588.27 | N24: 159893.35 | O24: 164402.78 | P24: 169782.11 | Q24: 183846.04 | R24: 174791.75 | S24: 187917.59 | T24: 190931.48 | U24: 188487.64 | V24: 154048.02 | W24: 164492.4 | X24: 175699.48 | Y24: 174761.24 | Z24: 168498.86 | AA24: 168460.49 | AB24: 166551.67 | AC24: 160271.05 | AD24: 163517.78 | AE24: 154389.55 | AF24: 125433.08 | AG24: 87708.301 | AH24: 104243.96 | AI24: 126737.11 | AJ24: 92422.554 | AK24: 67644.111
A25: Hard coal | B25: Exports | C25: 39922 | D25: 32707 | E25: 30927 | F25: 30678 | G25: 37673 | H25: 41987 | I25: 38358 | J25: 38531.1 | K25: 36724 | L25: 31959 | M25: 31052 | N25: 31047 | O25: 30840 | P25: 27219 | Q25: 27034 | R25: 26507.262 | S25: 24782.221 | T25: 21953.26 | U25: 18495.726 | V25: 17691.209 | W25: 18914.081 | X25: 15000.675 | Y25: 15309.931 | Z25: 17323.17 | AA25: 15444.408 | AB25: 14288.491 | AC25: 13414.84 | AD25: 10025.015 | AE25: 7366.959 | AF25: 7929.965 | AG25: 8304.125 | AH25: 10187.777 | AI25: 8772.614 | AJ25: 10291.62 | AK25: 7885.895
A26: Hard coal | B26: Change in stock | C26: 3003.549 | D26: 3117.314 | E26: -10976.999 | F26: 7972.82 | G26: 9260.656 | H26: 2277.928 | I26: 7321.913 | J26: -3728.356 | K26: 10003.58 | L26: 3440.67 | M26: 5078.793 | N26: 5500.39 | O26: 1213.611 | P26: 5544.411 | Q26: -3360.069 | R26: -2039.079 | S26: 2219.705 | T26: 7491.568 | U26: -11369.864 | V26: -6188.426 | W26: 6426.001 | X26: -1482.242 | Y26: -2881.132 | Z26: 11970.652 | AA26: -1226.342 | AB26: 6121.96 | AC26: 10893.549 | AD26: 2021.445 | AE26: 2274.123 | AF26: -4294.753 | AG26: 8549.191 | AH26: 14601.94 | AI26: -9205.383 | AJ26: -3499.952 | AK26: 5461.588
A27: Hard coal | B27: International maritime bunkers | C27: 0 | D27: 0 | E27: 0 | F27: 0 | G27: 0 | H27: 0 | I27: 0 | J27: 0 | K27: 0 | L27: 0 | M27: 0 | N27: 0 | O27: 0 | P27: 0 | Q27: 0 | R27: 0 | S27: 0 | T27: 0 | U27: 0 | V27: 0 | W27: 0 | X27: 0 | Y27: 0 | Z27: 0 | AA27: 0 | AB27: 0 | AC27: 0 | AD27: 0 | AE27: 0 | AF27: 0 | AG27: 0 | AH27: 0 | AI27: 0 | AJ27: 0 | AK27: :
A28: Hard coal | B28: Inland consumption - calculated | C28: 389865.81 | D28: 384362.71 | E28: 359321.93 | F28: 342578.62 | G28: 339084.57 | H28: 340469.1 | I28: 344111.3 | J28: 331014.6 | K28: 316519.9 | L28: 299488.1 | M28: 300697.07 | N28: 297318.74 | O28: 294099.39 | P28: 305329.52 | Q28: 309325.97 | R28: 294690.41 | S28: 306578.08 | T28: 310528.79 | U28: 282522.04 | V28: 241506.38 | W28: 260842.32 | X28: 264600.56 | Y28: 263908.18 | Z28: 260135.34 | AA28: 245406.74 | AB28: 248040.14 | AC28: 240761.76 | AD28: 232144.88 | AE28: 221263.08 | AF28: 178842 | AG28: 144877.83 | AH28: 166214.02 | AI28: 163650.15 | AJ28: 128733.16 | AK28: 110923.85
A29: Anthracite | B29: Indigenous production | C29: 0 | D29: 0 | E29: 0 | F29: 0 | G29: 0 | H29: 0 | I29: 0 | J29: 0 | K29: 0 | L29: 0 | M29: 0 | N29: 0 | O29: 0 | P29: 1901 | Q29: 5654 | R29: 5884 | S29: 5763 | T29: 5471 | U29: 5131 | V29: 5985 | W29: 5231 | X29: 4558 | Y29: 4266 | Z29: 2794 | AA29: 3366 | AB29: 2426 | AC29: 1737 | AD29: 1394 | AE29: 1122 | AF29: 0 | AG29: 0 | AH29: 0 | AI29: 0 | AJ29: 0 | AK29: 0
A30: Anthracite | B30: Transfer from other sources | C30: 0 | D30: 0 | E30: 0 | F30: 0 | G30: 0 | H30: 0 | I30: 0 | J30: 0 | K30: 0 | L30: 0 | M30: 0 | N30: 0 | O30: 0 | P30: 0 | Q30: 0 | R30: 0 | S30: 0 | T30: 0 | U30: 0 | V30: 0 | W30: 0 | X30: 0 | Y30: 0 | Z30: 0 | AA30: 0 | AB30: 0 | AC30: 0 | AD30: 0 | AE30: 0 | AF30: 0 | AG30: 0 | AH30: 0 | AI30: 0 | AJ30: 0 | AK30: 0
A31: Anthracite | B31: Imports | C31: 418.752 | D31: 305.394 | E31: 349.36 | F31: 325.2 | G31: 199.211 | H31: 158 | I31: 187.1 | J31: 93 | K31: 124 | L31: 116 | M31: 140.616 | N31: 137.884 | O31: 1396.022 | P31: 3263.097 | Q31: 4693.347 | R31: 4565.903 | S31: 3707.175 | T31: 5030.289 | U31: 6532.823 | V31: 4543.91 | W31: 4747.515 | X31: 7198.287 | Y31: 6205.09 | Z31: 5258.743 | AA31: 4789.985 | AB31: 4646.004 | AC31: 3238.671 | AD31: 3519.715 | AE31: 3955.609 | AF31: 4270.444 | AG31: 4041.591 | AH31: 3413.953 | AI31: 2772.073 | AJ31: 1420.663 | AK31: 1316.081
A32: Anthracite | B32: Exports | C32: 0 | D32: 0 | E32: 0 | F32: 0 | G32: 0 | H32: 0 | I32: 0 | J32: 0 | K32: 0 | L32: 0 | M32: 0 | N32: 0 | O32: 935 | P32: 816 | Q32: 932 | R32: 786.761 | S32: 671.003 | T32: 860.283 | U32: 834.075 | V32: 978.182 | W32: 1021.222 | X32: 846 | Y32: 888.229 | Z32: 444.147 | AA32: 572.023 | AB32: 396.001 | AC32: 244 | AD32: 225.289 | AE32: 200.367 | AF32: 968.878 | AG32: 1425.192 | AH32: 274.568 | AI32: 344.066 | AJ32: 260.275 | AK32: 179.106
A33: Anthracite | B33: Change in stock | C33: -1.551 | D33: 13.772 | E33: -0.68 | F33: 0 | G33: 0 | H33: 0 | I33: 5.3 | J33: 0 | K33: 1 | L33: -3 | M33: 0 | N33: 0 | O33: 52 | P33: -119 | Q33: -280 | R33: -374.758 | S33: -443.745 | T33: -15.807 | U33: -1973.822 | V33: -2564.122 | W33: -3031.26 | X33: 904.796 | Y33: 1839.629 | Z33: 1394.67 | AA33: 700.968 | AB33: 827.942 | AC33: 441.941 | AD33: 211.488 | AE33: 42.298 | AF33: -65.46 | AG33: -152.055 | AH33: -293.045 | AI33: -121.817 | AJ33: 87.401 | AK33: -107.43
A34: Anthracite | B34: International maritime bunkers | C34: 0 | D34: 0 | E34: 0 | F34: 0 | G34: 0 | H34: 0 | I34: 0 | J34: 0 | K34: 0 | L34: 0 | M34: 0 | N34: 0 | O34: 0 | P34: 0 | Q34: 0 | R34: 0 | S34: 0 | T34: 0 | U34: 0 | V34: 0 | W34: 0 | X34: 0 | Y34: 0 | Z34: 0 | AA34: 0 | AB34: 0 | AC34: 0 | AD34: 0 | AE34: 0 | AF34: 0 | AG34: 0 | AH34: 0 | AI34: 0 | AJ34: 0 | AK34: :
A35: Anthracite | B35: Inland consumption - calculated | C35: 417.201 | D35: 319.166 | E35: 348.68 | F35: 325.2 | G35: 199.211 | H35: 158 | I35: 192.4 | J35: 93 | K35: 125 | L35: 113 | M35: 140.616 | N35: 137.884 | O35: 513.022 | P35: 4229.097 | Q35: 9135.347 | R35: 9288.384 | S35: 8355.427 | T35: 9625.199 | U35: 8855.926 | V35: 6986.606 | W35: 5926.033 | X35: 11815.083 | Y35: 11422.49 | Z35: 9003.266 | AA35: 8284.93 | AB35: 7503.945 | AC35: 5173.612 | AD35: 4899.914 | AE35: 4919.54 | AF35: 3236.106 | AG35: 2464.344 | AH35: 2846.34 | AI35: 2306.19 | AJ35: 1247.789 | AK35: 1029.545
A36: Coking coal | B36: Indigenous production | C36: 91504 | D36: 81426 | E36: 80005 | F36: 74713 | G36: 69097 | H36: 71984 | I36: 65232 | J36: 63869 | K36: 55324 | L36: 53308 | M36: 44233 | N36: 42106 | O36: 41499 | P36: 41296 | Q36: 40476 | R36: 36378 | S36: 35425 | T36: 35063 | U36: 30090 | V36: 23504 | W36: 25826 | X36: 23923 | Y36: 23103 | Z36: 21431 | AA36: 21617 | AB36: 20916 | AC36: 18752 | AD36: 17678.173 | AE36: 15752.063 | AF36: 14103.6 | AG36: 13299.128 | AH36: 14085.578 | AI36: 13228.432 | AJ36: 12442.679 | AK36: 11909.465
A37: Coking coal | B37: Transfer from other sources | C37: 0 | D37: 0 | E37: 1 | F37: 0 | G37: 0 | H37: 28 | I37: 51 | J37: 150 | K37: 0 | L37: 0 | M37: 0 | N37: 0 | O37: 0 | P37: 0 | Q37: 0 | R37: 0 | S37: 0 | T37: 0 | U37: 0 | V37: 0 | W37: 0 | X37: 17 | Y37: 37 | Z37: 0 | AA37: 0 | AB37: 0 | AC37: 0 | AD37: 0 | AE37: 0 | AF37: 0 | AG37: 0 | AH37: 0 | AI37: 0 | AJ37: 93.691 | AK37: 0
A38: Coking coal | B38: Imports | C38: 49255 | D38: 45327 | E38: 46085 | F38: 42312 | G38: 45028 | H38: 47755.772 | I38: 47445.887 | J38: 49995.356 | K38: 50022.82 | L38: 44055.03 | M38: 44135.507 | N38: 43027.911 | O38: 41056.066 | P38: 39517.998 | Q38: 44864.104 | R38: 45224.221 | S38: 47252.939 | T38: 50358.25 | U38: 49136.165 | V38: 30549.511 | W38: 40875.15 | X38: 40127.988 | Y38: 38724.899 | Z38: 36469.843 | AA38: 38396.797 | AB38: 34852.894 | AC38: 39701.995 | AD38: 41749.625 | AE38: 41233.329 | AF38: 38364.365 | AG38: 31435.422 | AH38: 33909.713 | AI38: 34188.72 | AJ38: 31964.361 | AK38: 30463.144
A39: Coking coal | B39: Exports | C39: 19732 | D39: 16450 | E39: 16312 | F39: 17395 | G39: 15811 | H39: 18207 | I39: 14821 | J39: 12971 | K39: 10207 | L39: 10187 | M39: 8805 | N39: 6965 | O39: 6915 | P39: 6472 | Q39: 6357 | R39: 6424 | S39: 8046 | T39: 7288.073 | U39: 5845 | V39: 5898 | W39: 5537 | X39: 4296 | Y39: 4734 | Z39: 4516 | AA39: 4557 | AB39: 4202.813 | AC39: 4526 | AD39: 4219.714 | AE39: 4117.249 | AF39: 3461.457 | AG39: 3156.311 | AH39: 4430.224 | AI39: 3960.477 | AJ39: 3860.104 | AK39: 3294.169
A40: Coking coal | B40: Change in stock | C40: 288 | D40: 454 | E40: -4333 | F40: -506 | G40: 3509 | H40: 678.228 | I40: 11.113 | J40: -1222.356 | K40: 671.18 | L40: -4.03 | M40: 947.493 | N40: -637.911 | O40: -169.066 | P40: 1231.002 | Q40: -223.104 | R40: -1527.721 | S40: 1127.275 | T40: 30.808 | U40: -1168.876 | V40: 2925.256 | W40: -1633.752 | X40: 469.013 | Y40: 3735.758 | Z40: 838.007 | AA40: -218.481 | AB40: 659.885 | AC40: 660.34 | AD40: 287.19 | AE40: 1281.368 | AF40: -671.643 | AG40: 1252.003 | AH40: 307.541 | AI40: -232.737 | AJ40: 118.625 | AK40: -192.004
A41: Coking coal | B41: International maritime bunkers | C41: 0 | D41: 0 | E41: 0 | F41: 0 | G41: 0 | H41: 0 | I41: 0 | J41: 0 | K41: 0 | L41: 0 | M41: 0 | N41: 0 | O41: 0 | P41: 0 | Q41: 0 | R41: 0 | S41: 0 | T41: 0 | U41: 0 | V41: 0 | W41: 0 | X41: 0 | Y41: 0 | Z41: 0 | AA41: 0 | AB41: 0 | AC41: 0 | AD41: 0 | AE41: 0 | AF41: 0 | AG41: 0 | AH41: 0 | AI41: 0 | AJ41: 0 | AK41: :
A42: Coking coal | B42: Inland consumption - calculated | C42: 121315 | D42: 110757 | E42: 105446 | F42: 99124 | G42: 101823 | H42: 102239 | I42: 97919 | J42: 99821 | K42: 95811 | L42: 87172 | M42: 80511 | N42: 77531 | O42: 75471 | P42: 75573 | Q42: 78760 | R42: 73650.5 | S42: 75759.214 | T42: 78163.985 | U42: 72212.289 | V42: 51080.767 | W42: 59530.398 | X42: 60241.001 | Y42: 60866.657 | Z42: 54222.85 | AA42: 55238.316 | AB42: 52225.966 | AC42: 54588.335 | AD42: 55495.274 | AE42: 54149.511 | AF42: 48334.865 | AG42: 42830.242 | AH42: 43872.608 | AI42: 43223.938 | AJ42: 40759.252 | AK42: 38886.436
A43: Other bituminous coal | B43: Indigenous production | C43: 185916.51 | D43: 179611 | E43: 171044.27 | F43: 162031.6 | G43: 162259.2 | H43: 161312.2 | I43: 162592.4 | J43: 160665.5 | K43: 138922.8 | L43: 130740.3 | M43: 125099 | N43: 119779 | O43: 116405 | P43: 112306 | Q43: 106043 | R43: 104772 | S43: 98767 | T43: 92017 | U43: 87718 | V43: 81023 | W43: 76759 | X43: 75778 | Y43: 78861 | Z43: 71716 | AA43: 67332 | AB43: 65547 | AC43: 61829 | AD43: 56820.119 | AE43: 54423.03 | AF43: 50951.903 | AG43: 43232.219 | AH43: 43099.681 | AI43: 41284.083 | AJ43: 37279.11 | AK43: 33386.371
A44: Other bituminous coal | B44: Transfer from other sources | C44: 1138 | D44: 1928 | E44: 1305 | F44: 983 | G44: 1456 | H44: 3060 | I44: 2197 | J44: 1534 | K44: 1107 | L44: 1516 | M44: 1750 | N44: 1087 | O44: 1419 | P44: 1719 | Q44: 3701 | R44: 1411 | S44: 1268 | T44: 1508 | U44: 961 | V44: 826 | W44: 1022 | X44: 1108 | Y44: 1071 | Z44: 1048 | AA44: 1302 | AB44: 766 | AC44: 694 | AD44: 738.379 | AE44: 669.278 | AF44: 578.128 | AG44: 393.112 | AH44: 370.644 | AI44: 378.529 | AJ44: 286.701 | AK44: 408.213
...

Sheet DATA-GAS
A1: https://ec.europa.eu/eurostat/databrowser/view/NRG_CB_GAS__custom_11896525/default/table?lang=en
A2: Supply, transformation and consumption of gas
A5: Data extracted on 25/06/2025 19:15:15 from [ESTAT]
A6: Dataset: | B6: Supply, transformation and consumption of gas [nrg_cb_gas__custom_17248159]
A7: Last updated: | B7: 24/06/2025 23:00
A9: Time frequency | C9: Annual
A10: Unit of measure | C10: Terajoule (gross calorific value - GCV)
A11: Geopolitical entity (reporting) | C11: European Union - 27 countries (from 2020)
A13: TIME | B13: TIME | C13: 1990 | D13: 1991 | E13: 1992 | F13: 1993 | G13: 1994 | H13: 1995 | I13: 1996 | J13: 1997 | K13: 1998 | L13: 1999 | M13: 2000 | N13: 2001 | O13: 2002 | P13: 2003 | Q13: 2004 | R13: 2005 | S13: 2006 | T13: 2007 | U13: 2008 | V13: 2009 | W13: 2010 | X13: 2011 | Y13: 2012 | Z13: 2013 | AA13: 2014 | AB13: 2015 | AC13: 2016 | AD13: 2017 | AE13: 2018 | AF13: 2019 | AG13: 2020 | AH13: 2021 | AI13: 2022 | AJ13: 2023 | AK13: 2024
A14: SIEC (Labels) | B14: NRG_BAL (Labels)
A15: Manufactured gases | B15: Indigenous production | C15: 1411894.7 | D15: 1269576.1 | E15: 1166082.3 | F15: 1115938.7 | G15: 1117020.2 | H15: 1093373.2 | I15: 1032362.3 | J15: 1048471.4 | K15: 1032699.4 | L15: 921890.21 | M15: 970724.71 | N15: 907063.91 | O15: 911194.84 | P15: 936692.1 | Q15: 959501.85 | R15: 928971.46 | S15: 964932.06 | T15: 986904.5 | U15: 929712.75 | V15: 666126.35 | W15: 850823.39 | X15: 837590.79 | Y15: 827106.21 | Z15: 819499.68 | AA15: 840209.47 | AB15: 844132.62 | AC15: 829030.13 | AD15: 838442.3 | AE15: 828051.63 | AF15: 786074.07 | AG15: 675870.58 | AH15: 753738.78 | AI15: 695597.86 | AJ15: 660223.9 | AK15: 640807.21
A16: Manufactured gases | B16: Transfer from other sources | C16: 53923 | D16: 35622 | E16: 30338 | F16: 27728 | G16: 21990 | H16: 20623 | I16: 19058 | J16: 8739 | K16: 9337 | L16: 8891 | M16: 9456 | N16: 4795 | O16: 4394 | P16: 4158 | Q16: 4941 | R16: 4886 | S16: 4493 | T16: 3847 | U16: 3799 | V16: 3058 | W16: 3104 | X16: 721 | Y16: 278 | Z16: 247 | AA16: 299 | AB16: 573 | AC16: 221 | AD16: 549 | AE16: 701 | AF16: 496 | AG16: 383 | AH16: 33 | AI16: 0 | AJ16: 28 | AK16: 0
A17: Manufactured gases | B17: Imports | C17: 207 | D17: 213 | E17: 204 | F17: 183 | G17: 75 | H17: 0 | I17: 0 | J17: 0 | K17: 0 | L17: 0 | M17: 0 | N17: 0 | O17: 0 | P17: 0 | Q17: 0 | R17: 0 | S17: 0 | T17: 0 | U17: 0 | V17: 0 | W17: 0 | X17: 0 | Y17: 0 | Z17: 0 | AA17: 0 | AB17: 0 | AC17: 0 | AD17: 0 | AE17: 0 | AF17: 0 | AG17: 0 | AH17: 0 | AI17: 0 | AJ17: 0 | AK17: 0
A18: Manufactured gases | B18: Exports | C18: 212 | D18: 216 | E18: 198 | F18: 180 | G18: 0 | H18: 0 | I18: 0 | J18: 0 | K18: 0 | L18: 0 | M18: 0 | N18: 0 | O18: 0 | P18: 0 | Q18: 0 | R18: 0 | S18: 0 | T18: 0 | U18: 0 | V18: 0 | W18: 0 | X18: 0 | Y18: 0 | Z18: 0 | AA18: 0 | AB18: 0 | AC18: 0 | AD18: 0 | AE18: 0 | AF18: 0 | AG18: 0 | AH18: 0 | AI18: 0 | AJ18: 0 | AK18: 0
A19: Manufactured gases | B19: Change in stock | C19: 1794 | D19: 1602 | E19: 3563 | F19: 2486 | G19: 0 | H19: 0 | I19: 2 | J19: 0 | K19: 0 | L19: 0 | M19: 0 | N19: 0 | O19: 0 | P19: 0 | Q19: 0 | R19: 0 | S19: 0 | T19: 0 | U19: 0 | V19: 0 | W19: 0 | X19: 0 | Y19: 0 | Z19: 0 | AA19: 0 | AB19: 0 | AC19: 0 | AD19: 0 | AE19: 0 | AF19: 0 | AG19: 0 | AH19: 0 | AI19: 0 | AJ19: 0 | AK19: 0
A20: Manufactured gases | B20: International maritime bunkers | C20: 0 | D20: 0 | E20: 0 | F20: 0 | G20: 0 | H20: 0 | I20: 0 | J20: 0 | K20: 0 | L20: 0 | M20: 0 | N20: 0 | O20: 0 | P20: 0 | Q20: 0 | R20: 0 | S20: 0 | T20: 0 | U20: 0 | V20: 0 | W20: 0 | X20: 0 | Y20: 0 | Z20: 0 | AA20: 0 | AB20: 0 | AC20: 0 | AD20: 0 | AE20: 0 | AF20: 0 | AG20: 0 | AH20: 0 | AI20: 0 | AJ20: 0 | AK20: :
A21: Manufactured gases | B21: Inland consumption - calculated | C21: 1467606.7 | D21: 1306797.1 | E21: 1199989.3 | F21: 1146155.7 | G21: 1139085.2 | H21: 1113996.2 | I21: 1051422.3 | J21: 1057210.4 | K21: 1042036.4 | L21: 930781.21 | M21: 980180.71 | N21: 911858.91 | O21: 915588.84 | P21: 940850.1 | Q21: 964442.85 | R21: 933857.46 | S21: 969425.06 | T21: 990751.5 | U21: 933511.75 | V21: 669184.35 | W21: 853927.39 | X21: 838311.79 | Y21: 827384.21 | Z21: 819746.68 | AA21: 840508.47 | AB21: 844705.62 | AC21: 829251.13 | AD21: 838991.3 | AE21: 828752.63 | AF21: 786570.07 | AG21: 676253.58 | AH21: 753771.78 | AI21: 695597.86 | AJ21: 660251.9 | AK21: 640807.21
A22: Coke oven gas | B22: Indigenous production | C22: 623526 | D22: 541942.28 | E22: 512077.72 | F22: 475648.83 | G22: 471113.02 | H22: 464061.67 | I22: 447815.13 | J22: 444540.02 | K22: 438591.29 | L22: 373395.16 | M22: 387370.82 | N22: 352465 | O22: 343092.51 | P22: 348306.1 | Q22: 349586.58 | R22: 333940.32 | S22: 353439.45 | T22: 362016.33 | U22: 347307.89 | V22: 261791.03 | W22: 316420.14 | X22: 312988.43 | Y22: 313280.47 | Z22: 307167.28 | AA22: 308776.01 | AB22: 315677.81 | AC22: 312051.97 | AD22: 308086.26 | AE22: 277101.8 | AF22: 266599.74 | AG22: 242473.14 | AH22: 263411.61 | AI22: 247161.21 | AJ22: 242472.7 | AK22: 216582.64
A23: Coke oven gas | B23: Transfer from other sources | C23: 4740 | D23: 5261 | E23: 3816 | F23: 1734 | G23: 109 | H23: 3 | I23: 0 | J23: 0 | K23: 0 | L23: 0 | M23: 0 | N23: 0 | O23: 0 | P23: 0 | Q23: 0 | R23: 0 | S23: 0 | T23: 0 | U23: 0 | V23: 0 | W23: 0 | X23: 0 | Y23: 0 | Z23: 0 | AA23: 0 | AB23: 0 | AC23: 0 | AD23: 0 | AE23: 0 | AF23: 0 | AG23: 0 | AH23: 0 | AI23: 0 | AJ23: 0 | AK23: 0
A24: Coke oven gas | B24: Imports | C24: 0 | D24: 0 | E24: 0 | F24: 0 | G24: 0 | H24: 0 | I24: 0 | J24: 0 | K24: 0 | L24: 0 | M24: 0 | N24: 0 | O24: 0 | P24: 0 | Q24: 0 | R24: 0 | S24: 0 | T24: 0 | U24: 0 | V24: 0 | W24: 0 | X24: 0 | Y24: 0 | Z24: 0 | AA24: 0 | AB24: 0 | AC24: 0 | AD24: 0 | AE24: 0 | AF24: 0 | AG24: 0 | AH24: 0 | AI24: 0 | AJ24: 0 | AK24: 0
A25: Coke oven gas | B25: Exports | C25: 0 | D25: 0 | E25: 0 | F25: 0 | G25: 0 | H25: 0 | I25: 0 | J25: 0 | K25: 0 | L25: 0 | M25: 0 | N25: 0 | O25: 0 | P25: 0 | Q25: 0 | R25: 0 | S25: 0 | T25: 0 | U25: 0 | V25: 0 | W25: 0 | X25: 0 | Y25: 0 | Z25: 0 | AA25: 0 | AB25: 0 | AC25: 0 | AD25: 0 | AE25: 0 | AF25: 0 | AG25: 0 | AH25: 0 | AI25: 0 | AJ25: 0 | AK25: 0
A26: Coke oven gas | B26: Change in stock | C26: 0 | D26: 0 | E26: -1 | F26: 2 | G26: 0 | H26: 0 | I26: 0 | J26: 0 | K26: 0 | L26: 0 | M26: 0 | N26: 0 | O26: 0 | P26: 0 | Q26: 0 | R26: 0 | S26: 0 | T26: 0 | U26: 0 | V26: 0 | W26: 0 | X26: 0 | Y26: 0 | Z26: 0 | AA26: 0 | AB26: 0 | AC26: 0 | AD26: 0 | AE26: 0 | AF26: 0 | AG26: 0 | AH26: 0 | AI26: 0 | AJ26: 0 | AK26: 0
A27: Coke oven gas | B27: International maritime bunkers | C27: 0 | D27: 0 | E27: 0 | F27: 0 | G27: 0 | H27: 0 | I27: 0 | J27: 0 | K27: 0 | L27: 0 | M27: 0 | N27: 0 | O27: 0 | P27: 0 | Q27: 0 | R27: 0 | S27: 0 | T27: 0 | U27: 0 | V27: 0 | W27: 0 | X27: 0 | Y27: 0 | Z27: 0 | AA27: 0 | AB27: 0 | AC27: 0 | AD27: 0 | AE27: 0 | AF27: 0 | AG27: 0 | AH27: 0 | AI27: 0 | AJ27: 0 | AK27: :
A28: Coke oven gas | B28: Inland consumption - calculated | C28: 628266 | D28: 547203.28 | E28: 515892.72 | F28: 477384.83 | G28: 471222.02 | H28: 464064.67 | I28: 447815.13 | J28: 444540.02 | K28: 438591.29 | L28: 373395.16 | M28: 387370.82 | N28: 352465 | O28: 343092.51 | P28: 348306.1 | Q28: 349586.58 | R28: 333940.32 | S28: 353439.45 | T28: 362016.33 | U28: 347307.89 | V28: 261791.03 | W28: 316420.14 | X28: 312988.43 | Y28: 313280.47 | Z28: 307167.28 | AA28: 308776.01 | AB28: 315677.81 | AC28: 312051.97 | AD28: 308086.26 | AE28: 277101.8 | AF28: 266599.74 | AG28: 242473.14 | AH28: 263411.61 | AI28: 247161.21 | AJ28: 242472.7 | AK28: 216582.64
A29: Gas works gas | B29: Indigenous production | C29: 132889.73 | D29: 127251.77 | E29: 95500.583 | F29: 64669.899 | G29: 39401.158 | H29: 26495.525 | I29: 20818.183 | J29: 18980.401 | K29: 15954.111 | L29: 14842.049 | M29: 16620.892 | N29: 16570.914 | O29: 16973.323 | P29: 17887.998 | Q29: 17659.275 | R29: 18637.815 | S29: 19596.088 | T29: 19114.262 | U29: 21077.033 | V29: 20694.579 | W29: 21237.769 | X29: 21397.123 | Y29: 20421.595 | Z29: 19804.012 | AA29: 20473.207 | AB29: 20390.404 | AC29: 18323.191 | AD29: 17333.299 | AE29: 17159.383 | AF29: 15917.089 | AG29: 11968.83 | AH29: 2646.456 | AI29: 2638.007 | AJ29: 2580.204 | AK29: 0
A30: Gas works gas | B30: Transfer from other sources | C30: 49183 | D30: 30361 | E30: 26522 | F30: 25994 | G30: 21881 | H30: 20620 | I30: 19058 | J30: 8739 | K30: 9337 | L30: 8891 | M30: 9456 | N30: 4795 | O30: 4394 | P30: 4158 | Q30: 3945 | R30: 4073 | S30: 3850 | T30: 3244 | U30: 3285 | V30: 2900 | W30: 2506 | X30: 252 | Y30: 146 | Z30: 99 | AA30: 58 | AB30: 15 | AC30: 14 | AD30: 0 | AE30: 0 | AF30: 0 | AG30: 0 | AH30: 0 | AI30: 0 | AJ30: 0 | AK30: 0
A31: Gas works gas | B31: Imports | C31: 207 | D31: 213 | E31: 204 | F31: 183 | G31: 75 | H31: 0 | I31: 0 | J31: 0 | K31: 0 | L31: 0 | M31: 0 | N31: 0 | O31: 0 | P31: 0 | Q31: 0 | R31: 0 | S31: 0 | T31: 0 | U31: 0 | V31: 0 | W31: 0 | X31: 0 | Y31: 0 | Z31: 0 | AA31: 0 | AB31: 0 | AC31: 0 | AD31: 0 | AE31: 0 | AF31: 0 | AG31: 0 | AH31: 0 | AI31: 0 | AJ31: 0 | AK31: 0
A32: Gas works gas | B32: Exports | C32: 212 | D32: 216 | E32: 198 | F32: 180 | G32: 0 | H32: 0 | I32: 0 | J32: 0 | K32: 0 | L32: 0 | M32: 0 | N32: 0 | O32: 0 | P32: 0 | Q32: 0 | R32: 0 | S32: 0 | T32: 0 | U32: 0 | V32: 0 | W32: 0 | X32: 0 | Y32: 0 | Z32: 0 | AA32: 0 | AB32: 0 | AC32: 0 | AD32: 0 | AE32: 0 | AF32: 0 | AG32: 0 | AH32: 0 | AI32: 0 | AJ32: 0 | AK32: 0
A33: Gas works gas | B33: Change in stock | C33: 1794 | D33: 1602 | E33: 3564 | F33: 2484 | G33: 0 | H33: 0 | I33: 2 | J33: 0 | K33: 0 | L33: 0 | M33: 0 | N33: 0 | O33: 0 | P33: 0 | Q33: 0 | R33: 0 | S33: 0 | T33: 0 | U33: 0 | V33: 0 | W33: 0 | X33: 0 | Y33: 0 | Z33: 0 | AA33: 0 | AB33: 0 | AC33: 0 | AD33: 0 | AE33: 0 | AF33: 0 | AG33: 0 | AH33: 0 | AI33: 0 | AJ33: 0 | AK33: 0
A34: Gas works gas | B34: International maritime bunkers | C34: 0 | D34: 0 | E34: 0 | F34: 0 | G34: 0 | H34: 0 | I34: 0 | J34: 0 | K34: 0 | L34: 0 | M34: 0 | N34: 0 | O34: 0 | P34: 0 | Q34: 0 | R34: 0 | S34: 0 | T34: 0 | U34: 0 | V34: 0 | W34: 0 | X34: 0 | Y34: 0 | Z34: 0 | AA34: 0 | AB34: 0 | AC34: 0 | AD34: 0 | AE34: 0 | AF34: 0 | AG34: 0 | AH34: 0 | AI34: 0 | AJ34: 0 | AK34: :
A35: Gas works gas | B35: Inland consumption - calculated | C35: 183861.73 | D35: 159211.77 | E35: 125592.58 | F35: 93150.899 | G35: 61357.158 | H35: 47115.525 | I35: 39878.183 | J35: 27719.401 | K35: 25291.111 | L35: 23733.049 | M35: 26076.892 | N35: 21365.914 | O35: 21367.323 | P35: 22045.998 | Q35: 21604.275 | R35: 22710.815 | S35: 23446.088 | T35: 22358.262 | U35: 24362.033 | V35: 23594.579 | W35: 23743.769 | X35: 21649.123 | Y35: 20567.595 | Z35: 19903.012 | AA35: 20531.207 | AB35: 20405.404 | AC35: 18337.191 | AD35: 17333.299 | AE35: 17159.383 | AF35: 15917.089 | AG35: 11968.83 | AH35: 2646.456 | AI35: 2638.007 | AJ35: 2580.204 | AK35: 0
A36: Blast furnace gas | B36: Indigenous production | C36: 648036 | D36: 592286 | E36: 551126 | F36: 545763 | G36: 580789 | H36: 575457 | I36: 542583 | J36: 562693 | K36: 549634 | L36: 506955 | M36: 538588 | N36: 509895 | O36: 521508 | P36: 529131 | Q36: 548060 | R36: 530551.18 | S36: 546494.81 | T36: 559327.03 | U36: 522087.39 | V36: 350800.66 | W36: 468295.91 | X36: 453053.07 | Y36: 443195.83 | Z36: 441166.75 | AA36: 452035.3 | AB36: 443838.36 | AC36: 435285.71 | AD36: 449671.37 | AE36: 480690.03 | AF36: 451240.37 | AG36: 376361.68 | AH36: 441988.42 | AI36: 400971.52 | AJ36: 373319.18 | AK36: 382849.98
A37: Blast furnace gas | B37: Transfer from other sources | C37: 0 | D37: 0 | E37: 0 | F37: 0 | G37: 0 | H37: 0 | I37: 0 | J37: 0 | K37: 0 | L37: 0 | M37: 0 | N37: 0 | O37: 0 | P37: 0 | Q37: 996 | R37: 813 | S37: 643 | T37: 603 | U37: 514 | V37: 158 | W37: 598 | X37: 469 | Y37: 132 | Z37: 148 | AA37: 241 | AB37: 558 | AC37: 207 | AD37: 549 | AE37: 701 | AF37: 496 | AG37: 383 | AH37: 33 | AI37: 0 | AJ37: 28 | AK37: 0
A38: Blast furnace gas | B38: Imports | C38: 0 | D38: 0 | E38: 0 | F38: 0 | G38: 0 | H38: 0 | I38: 0 | J38: 0 | K38: 0 | L38: 0 | M38: 0 | N38: 0 | O38: 0 | P38: 0 | Q38: 0 | R38: 0 | S38: 0 | T38: 0 | U38: 0 | V38: 0 | W38: 0 | X38: 0 | Y38: 0 | Z38: 0 | AA38: 0 | AB38: 0 | AC38: 0 | AD38: 0 | AE38: 0 | AF38: 0 | AG38: 0 | AH38: 0 | AI38: 0 | AJ38: 0 | AK38: 0
A39: Blast furnace gas | B39: Exports | C39: 0 | D39: 0 | E39: 0 | F39: 0 | G39: 0 | H39: 0 | I39: 0 | J39: 0 | K39: 0 | L39: 0 | M39: 0 | N39: 0 | O39: 0 | P39: 0 | Q39: 0 | R39: 0 | S39: 0 | T39: 0 | U39: 0 | V39: 0 | W39: 0 | X39: 0 | Y39: 0 | Z39: 0 | AA39: 0 | AB39: 0 | AC39: 0 | AD39: 0 | AE39: 0 | AF39: 0 | AG39: 0 | AH39: 0 | AI39: 0 | AJ39: 0 | AK39: 0
A40: Blast furnace gas | B40: Change in stock | C40: 0 | D40: 0 | E40: 0 | F40: 0 | G40: 0 | H40: 0 | I40: 0 | J40: 0 | K40: 0 | L40: 0 | M40: 0 | N40: 0 | O40: 0 | P40: 0 | Q40: 0 | R40: 0 | S40: 0 | T40: 0 | U40: 0 | V40: 0 | W40: 0 | X40: 0 | Y40: 0 | Z40: 0 | AA40: 0 | AB40: 0 | AC40: 0 | AD40: 0 | AE40: 0 | AF40: 0 | AG40: 0 | AH40: 0 | AI40: 0 | AJ40: 0 | AK40: 0
A41: Blast furnace gas | B41: International maritime bunkers | C41: 0 | D41: 0 | E41: 0 | F41: 0 | G41: 0 | H41: 0 | I41: 0 | J41: 0 | K41: 0 | L41: 0 | M41: 0 | N41: 0 | O41: 0 | P41: 0 | Q41: 0 | R41: 0 | S41: 0 | T41: 0 | U41: 0 | V41: 0 | W41: 0 | X41: 0 | Y41: 0 | Z41: 0 | AA41: 0 | AB41: 0 | AC41: 0 | AD41: 0 | AE41: 0 | AF41: 0 | AG41: 0 | AH41: 0 | AI41: 0 | AJ41: 0 | AK41: :
A42: Blast furnace gas | B42: Inland consumption - calculated | C42: 648036 | D42: 592286 | E42: 551126 | F42: 545763 | G42: 580789 | H42: 575457 | I42: 542583 | J42: 562693 | K42: 549634 | L42: 506955 | M42: 538588 | N42: 509895 | O42: 521508 | P42: 529131 | Q42: 549056 | R42: 531364.18 | S42: 547137.81 | T42: 559930.03 | U42: 522601.39 | V42: 350958.66 | W42: 468893.91 | X42: 453522.07 | Y42: 443327.83 | Z42: 441314.75 | AA42: 452276.3 | AB42: 444396.36 | AC42: 435492.71 | AD42: 450220.37 | AE42: 481391.03 | AF42: 451736.37 | AG42: 376744.68 | AH42: 442021.42 | AI42: 400971.52 | AJ42: 373347.18 | AK42: 382849.98
A43: Other recovered gases | B43: Indigenous production | C43: 7443 | D43: 8096 | E43: 7378 | F43: 29857 | G43: 25717 | H43: 27359 | I43: 21146 | J43: 22258 | K43: 28520 | L43: 26698 | M43: 28145 | N43: 28133 | O43: 29621 | P43: 41367 | Q43: 44196 | R43: 45842.147 | S43: 45401.721 | T43: 46446.883 | U43: 39240.439 | V43: 32840.079 | W43: 44869.572 | X43: 50152.161 | Y43: 50208.321 | Z43: 51361.64 | AA43: 58924.948 | AB43: 64226.045 | AC43: 63369.25 | AD43: 63351.364 | AE43: 53100.417 | AF43: 52316.86 | AG43: 45066.936 | AH43: 45692.292 | AI43: 44827.114 | AJ43: 41851.815 | AK43: 41374.59
A44: Other recovered gases | B44: Transfer from other sources | C44: 0 | D44: 0 | E44: 0 | F44: 0 | G44: 0 | H44: 0 | I44: 0 | J44: 0 | K44: 0 | L44: 0 | M44: 0 | N44: 0 | O44: 0 | P44: 0 | Q44: 0 | R44: 0 | S44: 0 | T44: 0 | U44: 0 | V44: 0 | W44: 0 | X44: 0 | Y44: 0 | Z44: 0 | AA44: 0 | AB44: 0 | AC44: 0 | AD44: 0 | AE44: 0 | AF44: 0 | AG44: 0 | AH44: 0 | AI44: 0 | AJ44: 0 | AK44: 0
...

Sheet DATA-ELE
A1: https://ec.europa.eu/eurostat/databrowser/view/NRG_IND_PEHNF__custom_11896696/default/table?lang=en
A2: Gross production of electricity and derived heat from non-combustible fuels by type of plant and operator
A4: Data extracted on 25/06/2025 19:21:37 from [ESTAT]
A5: Dataset: | B5: Gross production of electricity and derived heat from non-combustible fuels by type of plant and operator [nrg_ind_pehnf__custom_17248230]
A6: Last updated: | B6: 24/06/2025 23:00
A8: Time frequency | C8: Annual
A9: Type of plant | C9: Total
A10: Operator/Trader | C10: Total
A11: Energy balance | C11: Gross electricity production
A12: Unit of measure | C12: Gigawatt-hour
A13: Geopolitical entity (reporting) | C13: European Union - 27 countries (from 2020)
A15: TIME | B15: 1990 | C15: 1991 | D15: 1992 | E15: 1993 | F15: 1994 | G15: 1995 | H15: 1996 | I15: 1997 | J15: 1998 | K15: 1999 | L15: 2000 | M15: 2001 | N15: 2002 | O15: 2003 | P15: 2004 | Q15: 2005 | R15: 2006 | S15: 2007 | T15: 2008 | U15: 2009 | V15: 2010 | W15: 2011 | X15: 2012 | Y15: 2013 | Z15: 2014 | AA15: 2015 | AB15: 2016 | AC15: 2017 | AD15: 2018 | AE15: 2019 | AF15: 2020 | AG15: 2021 | AH15: 2022 | AI15: 2023 | AJ15: 2024
A16: SIEC (Labels)
A17: Hydro | B17: 301519.43 | C17: 315577.21 | D17: 329216.27 | E17: 335170.81 | F17: 344256.77 | G17: 346647.1 | H17: 350539.75 | I17: 353614.08 | J17: 367473.35 | K17: 367247.53 | L17: 379103.37 | M17: 401998.19 | N17: 345681.98 | O17: 335722.3 | P17: 355268.46 | Q17: 340546.18 | R17: 342707.54 | S17: 338894.13 | T17: 354878.27 | U17: 357662.57 | V17: 401279.58 | W17: 332848.8 | X17: 359551.4 | Y17: 396650.78 | Z17: 398608.49 | AA17: 363237.63 | AB17: 372711.2 | AC17: 322463.41 | AD17: 370234.44 | AE17: 345641.67 | AF17: 375485.65 | AG17: 374977.58 | AH17: 307441.55 | AI17: 361023.54 | AJ17: 402894.21
A18: Pure hydro power | B18: 271139.95 | C18: 283613.67 | D18: 298420.14 | E18: 304436.35 | F18: 312893.7 | G18: 313284.98 | H18: 312553.5 | I18: 317739.82 | J18: 328064.63 | K18: 328092.84 | L18: 337658.02 | M18: 354436.8 | N18: 301749.44 | O18: 288972.17 | P18: 308854.72 | Q18: 295997.08 | R18: 297964.01 | S18: 294584.3 | T18: 313054.88 | U18: 315702.42 | V18: 354325.37 | W18: 293410.83 | X18: 316879.44 | Y18: 350061.88 | Z18: 352851.32 | AA18: 321469.27 | AB18: 327996.06 | AC18: 281812.51 | AD18: 326818.54 | AE18: 306476.88 | AF18: 331707.81 | AG18: 330886.28 | AH18: 265425.68 | AI18: 315193.81 | AJ18: 350395.84
A19: Run-of-river hydro power | B19: 14736.598 | C19: 14806.452 | D19: 10331.407 | E19: 12627.334 | F19: 14478.11 | G19: 12128.583 | H19: 16475.34 | I19: 15925.808 | J19: 17423.643 | K19: 13074.426 | L19: 31039.054 | M19: 33592.965 | N19: 28464.795 | O19: 47407.113 | P19: 51148.281 | Q19: 71192.18 | R19: 74361.171 | S19: 74893.275 | T19: 77595.218 | U19: 82408.65 | V19: 87650.677 | W19: 75907.109 | X19: 82173.652 | Y19: 90716.719 | Z19: 92378.242 | AA19: 77725.11 | AB19: 85343.82 | AC19: 77013.641 | AD19: 81374.036 | AE19: 82454.449 | AF19: 86873.058 | AG19: 83550.378 | AH19: 66813.907 | AI19: 84507.803 | AJ19: :
A20: Mixed hydro power | B20: 16730.68 | C20: 16426.483 | D20: 14803.556 | E20: 16069.409 | F20: 17419.261 | G20: 17155.923 | H20: 19440.317 | I20: 18617.242 | J20: 19812.794 | K20: 19024.978 | L20: 19865.114 | M20: 26503.244 | N20: 20226.834 | O20: 24485.346 | P20: 22949.437 | Q20: 20095.583 | R20: 20912.484 | S20: 21187.197 | T20: 20532.041 | U20: 20844.203 | V20: 24870.063 | W20: 22409.665 | X20: 24572.026 | Y20: 27960.125 | Z20: 27336.926 | AA20: 23894.97 | AB20: 26917.57 | AC20: 22719.98 | AD20: 27043.575 | AE20: 23275.739 | AF20: 25837.969 | AG20: 27914.648 | AH20: 23336.529 | AI20: 27543.957 | AJ20: 32939.65
A21: Mixed hydro power - pumping | B21: 4234.003 | C21: 4437.288 | D21: 5546.722 | E21: 4742.717 | F21: 4488.26 | G21: 5213.388 | H21: 4812.387 | I21: 4606.219 | J21: 4937.325 | K21: 6298.971 | L21: 7344.935 | M21: 7531.974 | N21: 9379.453 | O21: 8814.084 | P21: 8613.123 | Q21: 9097.691 | R21: 8901.9 | S21: 8072.575 | T21: 7988.613 | U21: 7550.527 | V21: 7378.756 | W21: 8399.122 | X21: 9782.843 | Y21: 10012.635 | Z21: 10144.785 | AA21: 9381.881 | AB21: 9326.948 | AC21: 10186.521 | AD21: 9980.687 | AE21: 9494.13 | AF21: 10366.528 | AG21: 10354.55 | AH21: 12606.737 | AI21: 12884.157 | AJ21: 14685.844
A22: Pumped hydro power | B22: 13642.11 | C22: 15526.284 | D22: 15986.627 | E22: 14659.094 | F22: 13936.375 | G22: 16201.021 | H22: 18540.069 | I22: 17249.984 | J22: 19590.5 | K22: 20121.169 | L22: 21574.664 | M22: 21052.606 | N22: 23697.237 | O22: 22251.601 | P22: 23446.406 | Q22: 24437.127 | R22: 23817.42 | S22: 23115.841 | T22: 21286.414 | U22: 21111.261 | V22: 22075.637 | W22: 17024.021 | X22: 18095.307 | Y22: 18623.801 | Z22: 18413.728 | AA22: 17867.254 | AB22: 17791.024 | AC22: 17930.925 | AD22: 16372.319 | AE22: 15889.054 | AF22: 17939.869 | AG22: 16176.65 | AH22: 18678.653 | AI22: 18285.773 | AJ22: 19558.711
A23: Geothermal | B23: 3226 | C23: 3187 | D23: 3464 | E23: 3671 | F23: 3450 | G23: 3478 | H23: 3811 | I23: 3956 | J23: 4272 | K23: 4483 | L23: 4785 | M23: 4612 | N23: 4760.965 | O23: 5433.965 | P23: 5523.469 | Q23: 5397.673 | R23: 5615.65 | S23: 5772.528 | T23: 5731.578 | U23: 5546.27 | V23: 5602.409 | W23: 5946.971 | X23: 5820.339 | Y23: 6026.268 | Z23: 6303.352 | AA23: 6613.642 | AB23: 6732.88 | AC23: 6715.039 | AD23: 6654.991 | AE23: 6725.806 | AF23: 6717.256 | AG23: 6538.375 | AH23: 6427.79 | AI23: 6260.122 | AJ23: 6204.12
A24: Wind | B24: 769.272 | C24: 1085.49 | D24: 1517.573 | E24: 2137.653 | F24: 3151.337 | G24: 3677.149 | H24: 4388.685 | I24: 6693.733 | J24: 10399.518 | K24: 13355.739 | L24: 21280.039 | M24: 25744.024 | N24: 35068.957 | O24: 43314.85 | P24: 57537.557 | Q24: 68113.045 | R24: 78738.128 | S24: 99939.937 | T24: 113274.84 | U24: 124604.98 | V24: 139892.79 | W24: 165426.11 | X24: 187535.31 | Y24: 209560.27 | Z24: 222441.58 | AA24: 263313.24 | AB24: 266916.12 | AC24: 312436.08 | AD24: 320758.66 | AE24: 367283.27 | AF24: 398173.55 | AG24: 386958.79 | AH24: 421853.05 | AI24: 478096.61 | AJ24: 487567.04
A25: Wind on shore | B25: 79 | C25: 114 | D25: 268.083 | E25: 321.249 | F25: 455.333 | G25: 633.691 | H25: 868.618 | I25: 1415.176 | J25: 2435.573 | K25: 4051.239 | L25: 6500.245 | M25: 9257.427 | N25: 12315.73 | O25: 34824.881 | P25: 47486.979 | Q25: 57437.259 | R25: 65708.935 | S25: 82426.851 | T25: 93987.682 | U25: 101145.3 | V25: 116090.44 | W25: 157159.39 | X25: 177327.86 | Y25: 195574.41 | Z25: 204597.85 | AA25: 237160.14 | AB25: 236670.12 | AC25: 282210.7 | AD25: 288806.16 | AE25: 327066.44 | AF25: 350788.11 | AG25: 339104.14 | AH25: 371659.56 | AI25: 423040.99 | AJ25: 424011.77
A26: Wind off shore | B26: 0 | C26: 0 | D26: 0 | E26: 0 | F26: 0 | G26: 0 | H26: 0 | I26: 0 | J26: 0 | K26: 0 | L26: 0 | M26: 0 | N26: 0 | O26: 0 | P26: 56 | Q26: 62 | R26: 123.202 | S26: 436.549 | T26: 962.974 | U26: 1236.8 | V26: 4160.274 | W26: 6010.544 | X26: 6346.678 | Y26: 8092.138 | Z26: 10312.24 | AA26: 17638.658 | AB26: 22231.03 | AC26: 30225.382 | AD26: 31952.494 | AE26: 40216.837 | AF26: 47385.439 | AG26: 47854.649 | AH26: 50193.491 | AI26: 55055.613 | AJ26: 63555.249
A27: Solar thermal | B27: 0 | C27: 0 | D27: 0 | E27: 0 | F27: 0 | G27: 0 | H27: 0 | I27: 0 | J27: 0 | K27: 0 | L27: 0 | M27: 0 | N27: 0 | O27: 0 | P27: 0 | Q27: 0 | R27: 0 | S27: 8.01 | T27: 16.147 | U27: 103 | V27: 761.2 | W27: 1959 | X27: 3775.043 | Y27: 4769.747 | Z27: 5454.806 | AA27: 5593.237 | AB27: 5579.2 | AC27: 5883 | AD27: 4867 | AE27: 5683 | AF27: 4992 | AG27: 5176 | AH27: 4536 | AI27: 5165 | AJ27: 4540.03
A28: Solar photovoltaic | B28: 15.875 | C28: 19.15 | D28: 28.11 | E28: 31.212 | F28: 38.071 | G28: 45.96 | H28: 51.28 | I28: 61.44 | J28: 84.515 | K28: 86.961 | L28: 113.22 | M28: 180.502 | N28: 266.236 | O28: 415.335 | P28: 690.913 | Q28: 1458.688 | R28: 2489.47 | S28: 3766.517 | T28: 7421.474 | U28: 14000.981 | V28: 22486.763 | W28: 45372.833 | X28: 66372.064 | Y28: 79361.983 | Z28: 88717.234 | AA28: 95262.005 | AB28: 95456.117 | AC28: 102050.21 | AD28: 108079.16 | AE28: 118010.74 | AF28: 139804.46 | AG28: 159074.43 | AH28: 206036.96 | AI28: 246974.42 | AJ28: 295280.45
A29: Solar photovoltaic (< 20 kW) | B29: 0 | C29: 0 | D29: 0 | E29: 0 | F29: 0 | G29: 0 | H29: 0 | I29: 0 | J29: 0 | K29: 0 | L29: 0 | M29: 0 | N29: 0 | O29: 0 | P29: 0 | Q29: 0 | R29: 0 | S29: 0 | T29: 0 | U29: 80.949 | V29: 561.08 | W29: 1671.529 | X29: 2489.319 | Y29: 3430.023 | Z29: 3774.716 | AA29: 4119.152 | AB29: 4235.777 | AC29: 5493.318 | AD29: 4800.46 | AE29: 5261.441 | AF29: 5824.331 | AG29: 27.4 | AH29: : | AI29: : | AJ29: :
A30: Solar photovoltaic (20 kW - 1000 kW) | B30: 0 | C30: 0 | D30: 0 | E30: 0 | F30: 0 | G30: 0 | H30: 0 | I30: 0 | J30: 0 | K30: 0 | L30: 0 | M30: 0 | N30: 0 | O30: 0 | P30: 0 | Q30: 0 | R30: 0 | S30: 0 | T30: 0 | U30: 69.888 | V30: 1116.127 | W30: 6495.974 | X30: 11605.049 | Y30: 12774.382 | Z30: 13087.482 | AA30: 13496.243 | AB30: 13054.194 | AC30: 16721.363 | AD30: 13640.911 | AE30: 15095.34 | AF30: 17272.169 | AG30: 113.4 | AH30: : | AI30: : | AJ30: :
A31: Solar photovoltaic (1+ MW) | B31: 0 | C31: 0 | D31: 0 | E31: 0 | F31: 0 | G31: 0 | H31: 0 | I31: 0 | J31: 0 | K31: 0 | L31: 0 | M31: 2 | N31: 2 | O31: 1 | P31: 1 | Q31: 1 | R31: 1 | S31: 1 | T31: 343 | U31: 827.171 | V31: 1446.054 | W31: 5149.574 | X31: 8739.738 | Y31: 9888.287 | Z31: 10865.55 | AA31: 12064.156 | AB31: 12366.934 | AC31: 14790.662 | AD31: 16676.608 | AE31: 21477.495 | AF31: 29417.46 | AG31: 53268.634 | AH31: 72980.595 | AI31: 89796.164 | AJ31: :
A32: Solar photovoltaic (off grid) | B32: 0 | C32: 0 | D32: 0 | E32: 0 | F32: 0 | G32: 0 | H32: 0 | I32: 0 | J32: 0 | K32: 0 | L32: 0 | M32: 0 | N32: 0 | O32: 0 | P32: 0 | Q32: 0 | R32: 0 | S32: 0 | T32: 0 | U32: 0 | V32: 0 | W32: 0 | X32: 0 | Y32: 0 | Z32: 0 | AA32: 0 | AB32: 0 | AC32: 0 | AD32: 0 | AE32: 0 | AF32: 0 | AG32: 0 | AH32: : | AI32: : | AJ32: :
A33: Tide, wave, ocean | B33: 502.673 | C33: 517.295 | D33: 516.228 | E33: 494.244 | F33: 501.384 | G33: 507.416 | H33: 490.651 | I33: 509.514 | J33: 521.693 | K33: 514.993 | L33: 507.307 | M33: 484.933 | N33: 494.433 | O33: 490.368 | P33: 470.176 | Q33: 480.895 | R33: 464.265 | S33: 465.292 | T33: 465.119 | U33: 448.197 | V33: 476.397 | W33: 477.278 | X33: 457.989 | Y33: 413.574 | Z33: 480.533 | AA33: 487.445 | AB33: 500.561 | AC33: 521.712 | AD33: 479.93 | AE33: 498.964 | AF33: 508.764 | AG33: 502.791 | AH33: 513.478 | AI33: 461.277 | AJ33: 467.65
A34: Ambient heat (heat pumps) | B34: : | C34: : | D34: : | E34: : | F34: : | G34: : | H34: : | I34: : | J34: : | K34: : | L34: : | M34: : | N34: : | O34: : | P34: : | Q34: : | R34: : | S34: : | T34: : | U34: : | V34: : | W34: : | X34: : | Y34: : | Z34: : | AA34: : | AB34: : | AC34: : | AD34: : | AE34: : | AF34: : | AG34: : | AH34: : | AI34: : | AJ34: :
